<?xml version="1.0" ?>
<!-- Model from velocity_control.sdf -->
<sdf version="1.6">
  <model name='vehicle_blue'>
    <link name='chassis'>
      <pose>-0.151427 -0 0.175 0 -0 0</pose>
      <inertial>
        <mass>1.14395</mass>
        <inertia>
          <ixx>0.126164</ixx>
          <ixy>0</ixy>
          <ixz>0</ixz>
          <iyy>0.416519</iyy>
          <iyz>0</iyz>
          <izz>0.481014</izz>
        </inertia>
      </inertial>
      <visual name='visual'>
        <geometry>
          <box>
            <size>2.01142 1 0.568726</size>
          </box>
        </geometry>
        <material>
          <ambient>0.5 0.5 1.0 1</ambient>
          <diffuse>0.5 0.5 1.0 1</diffuse>
          <specular>0.0 0.0 1.0 1</specular>
        </material>
      </visual>
      <collision name='collision'>
        <geometry>
          <box>
            <size>2.01142 1 0.568726</size>
          </box>
        </geometry>
      </collision>
    </link>

    <link name='left_wheel'>
      <pose>0.554283 0.625029 -0.025 -1.5707 0 0</pose>
      <inertial>
        <mass>2</mass>
        <inertia>
          <ixx>0.145833</ixx>
          <ixy>0</ixy>
          <ixz>0</ixz>
          <iyy>0.145833</iyy>
          <iyz>0</iyz>
          <izz>0.125</izz>
        </inertia>
      </inertial>
      <visual name='visual'>
        <geometry>
          <sphere>
            <radius>0.3</radius>
          </sphere>
        </geometry>
        <material>
          <ambient>0.2 0.2 0.2 1</ambient>
          <diffuse>0.2 0.2 0.2 1</diffuse>
          <specular>0.2 0.2 0.2 1</specular>
        </material>
      </visual>
      <collision name='collision'>
        <geometry>
          <sphere>
            <radius>0.3</radius>
          </sphere>
        </geometry>
      </collision>
    </link>

    <link name='right_wheel'>
      <pose>0.554282 -0.625029 -0.025 -1.5707 0 0</pose>
      <inertial>
        <mass>2</mass>
        <inertia>
          <ixx>0.145833</ixx>
          <ixy>0</ixy>
          <ixz>0</ixz>
          <iyy>0.145833</iyy>
          <iyz>0</iyz>
          <izz>0.125</izz>
        </inertia>
      </inertial>
      <visual name='visual'>
        <geometry>
          <sphere>
            <radius>0.3</radius>
          </sphere>
        </geometry>
        <material>
          <ambient>0.2 0.2 0.2 1</ambient>
          <diffuse>0.2 0.2 0.2 1</diffuse>
          <specular>0.2 0.2 0.2 1</specular>
        </material>
      </visual>
      <collision name='collision'>
        <geometry>
          <sphere>
            <radius>0.3</radius>
          </sphere>
        </geometry>
      </collision>
    </link>

    <link name='caster'>
      <pose>-0.957138 -0 -0.125 0 -0 0</pose>
      <inertial>
        <mass>1</mass>
        <inertia>
          <ixx>0.1</ixx>
          <ixy>0</ixy>
          <ixz>0</ixz>
          <iyy>0.1</iyy>
          <iyz>0</iyz>
          <izz>0.1</izz>
        </inertia>
      </inertial>
      <visual name='visual'>
        <geometry>
          <sphere>
            <radius>0.2</radius>
          </sphere>
        </geometry>
        <material>
          <ambient>0.2 0.2 0.2 1</ambient>
          <diffuse>0.2 0.2 0.2 1</diffuse>
          <specular>0.2 0.2 0.2 1</specular>
        </material>
      </visual>
      <collision name='collision'>
        <geometry>
          <sphere>
            <radius>0.2</radius>
          </sphere>
        </geometry>
      </collision>
    </link>

    <joint name='left_wheel_joint' type='revolute'>
      <parent>chassis</parent>
      <child>left_wheel</child>
      <axis>
        <xyz>0 0 1</xyz>
        <limit>
          <lower>-1.79769e+308</lower>
          <upper>1.79769e+308</upper>
        </limit>
      </axis>
    </joint>

    <joint name='right_wheel_joint' type='revolute'>
      <parent>chassis</parent>
      <child>right_wheel</child>
      <axis>
        <xyz>0 0 1</xyz>
        <limit>
          <lower>-1.79769e+308</lower>
          <upper>1.79769e+308</upper>
        </limit>
      </axis>
    </joint>

    <joint name='caster_wheel' type='ball'>
      <parent>chassis</parent>
      <child>caster</child>
    </joint>

    <plugin
      filename="ignition-gazebo-velocity-control-system"
      name="gz::sim::systems::VelocityControl">
    </plugin>

    <plugin
      filename="ignition-gazebo-pose-publisher-system"
      name="gz::sim::systems::PosePublisher">
      <publish_link_pose>false</publish_link_pose>
      <publish_visual_pose>false</publish_visual_pose>
      <publish_collision_pose>false</publish_collision_pose>
      <publish_sensor_pose>false</publish_sensor_pose>
      <publish_nested_model_pose>true</publish_nested_model_pose>
      <publish_model_pose>true</publish_model_pose>
      <use_pose_vector_msg>true</use_pose_vector_msg>
      <update_frequency>100</update_frequency>
    </plugin>

  </model>
</sdf>